2020-01-22 18:51:58,153 - login.py[line:38] - INFO: 模拟登陆成功
2020-01-22 19:17:32,546 - login.py[line:37] - INFO: 模拟登陆成功
2020-01-22 19:18:26,558 - login.py[line:41] - INFO: 模拟登陆成功
2020-01-22 19:18:52,509 - login.py[line:41] - INFO: 模拟登陆成功
2020-01-22 19:20:20,131 - login.py[line:41] - INFO: 模拟登陆成功
2020-01-22 19:20:45,176 - login.py[line:41] - INFO: 模拟登陆成功
2020-01-22 19:23:37,072 - login.py[line:43] - INFO: 模拟登陆成功
2020-01-22 19:26:07,921 - login.py[line:43] - INFO: 模拟登陆成功
2020-01-22 19:36:09,276 - connectionpool.py[line:745] - WARNING: Retrying (Retry(total=2, connect=None, read=None, redirect=None, status=None)) after connection broken by 'NewConnectionError('<urllib3.connection.HTTPConnection object at 0x00000210A8751BA8>: Failed to establish a new connection: [WinError 10061] 由于目标计算机积极拒绝，无法连接。')': /wd/hub/session/601588a0-3d0b-11ea-9a39-bdebf839b07d/element
2020-01-22 19:36:11,290 - connectionpool.py[line:745] - WARNING: Retrying (Retry(total=1, connect=None, read=None, redirect=None, status=None)) after connection broken by 'NewConnectionError('<urllib3.connection.HTTPConnection object at 0x00000210A876D128>: Failed to establish a new connection: [WinError 10061] 由于目标计算机积极拒绝，无法连接。')': /wd/hub/session/601588a0-3d0b-11ea-9a39-bdebf839b07d/element
2020-01-22 19:36:13,301 - connectionpool.py[line:745] - WARNING: Retrying (Retry(total=0, connect=None, read=None, redirect=None, status=None)) after connection broken by 'NewConnectionError('<urllib3.connection.HTTPConnection object at 0x00000210A876D390>: Failed to establish a new connection: [WinError 10061] 由于目标计算机积极拒绝，无法连接。')': /wd/hub/session/601588a0-3d0b-11ea-9a39-bdebf839b07d/element
2020-01-22 19:37:45,013 - connectionpool.py[line:745] - WARNING: Retrying (Retry(total=2, connect=None, read=None, redirect=None, status=None)) after connection broken by 'NewConnectionError('<urllib3.connection.HTTPConnection object at 0x0000020370731B70>: Failed to establish a new connection: [WinError 10061] 由于目标计算机积极拒绝，无法连接。')': /wd/hub/session/97bfde90-3d0b-11ea-8fbc-115b986e4334/element
2020-01-22 19:37:47,022 - connectionpool.py[line:745] - WARNING: Retrying (Retry(total=1, connect=None, read=None, redirect=None, status=None)) after connection broken by 'NewConnectionError('<urllib3.connection.HTTPConnection object at 0x00000203707590B8>: Failed to establish a new connection: [WinError 10061] 由于目标计算机积极拒绝，无法连接。')': /wd/hub/session/97bfde90-3d0b-11ea-8fbc-115b986e4334/element
2020-01-22 19:37:49,031 - connectionpool.py[line:745] - WARNING: Retrying (Retry(total=0, connect=None, read=None, redirect=None, status=None)) after connection broken by 'NewConnectionError('<urllib3.connection.HTTPConnection object at 0x0000020370759048>: Failed to establish a new connection: [WinError 10061] 由于目标计算机积极拒绝，无法连接。')': /wd/hub/session/97bfde90-3d0b-11ea-8fbc-115b986e4334/element
2020-01-22 19:41:05,852 - login.py[line:45] - INFO: 模拟登陆成功
2020-01-22 19:41:35,133 - login.py[line:45] - INFO: 模拟登陆成功
2020-01-22 19:51:18,413 - login.py[line:41] - INFO: 模拟登陆成功
2020-01-22 20:34:58,206 - log.py[line:228] - ERROR: Internal Server Error: /index/
Traceback (most recent call last):
  File "h:\django_learn\env\lib\site-packages\django\core\handlers\exception.py", line 34, in inner
    response = get_response(request)
  File "h:\django_learn\env\lib\site-packages\django\core\handlers\base.py", line 115, in _get_response
    response = self.process_exception_by_middleware(e, request)
  File "h:\django_learn\env\lib\site-packages\django\core\handlers\base.py", line 113, in _get_response
    response = wrapped_callback(request, *callback_args, **callback_kwargs)
  File "H:\django_learn\hello\hello\views.py", line 8, in hello
    return JsonResponse(g1)
  File "h:\django_learn\env\lib\site-packages\django\http\response.py", line 581, in __init__
    'In order to allow non-dict objects to be serialized set the '
TypeError: In order to allow non-dict objects to be serialized set the safe parameter to False.
2020-01-22 20:36:28,922 - log.py[line:228] - ERROR: Internal Server Error: /index/
Traceback (most recent call last):
  File "h:\django_learn\env\lib\site-packages\django\core\handlers\exception.py", line 34, in inner
    response = get_response(request)
  File "h:\django_learn\env\lib\site-packages\django\core\handlers\base.py", line 115, in _get_response
    response = self.process_exception_by_middleware(e, request)
  File "h:\django_learn\env\lib\site-packages\django\core\handlers\base.py", line 113, in _get_response
    response = wrapped_callback(request, *callback_args, **callback_kwargs)
  File "H:\django_learn\hello\hello\views.py", line 9, in hello
    return JsonResponse(g1)
  File "h:\django_learn\env\lib\site-packages\django\http\response.py", line 581, in __init__
    'In order to allow non-dict objects to be serialized set the '
TypeError: In order to allow non-dict objects to be serialized set the safe parameter to False.
2020-01-22 20:38:33,382 - log.py[line:228] - ERROR: Internal Server Error: /index/
Traceback (most recent call last):
  File "h:\django_learn\env\lib\site-packages\django\core\handlers\exception.py", line 34, in inner
    response = get_response(request)
  File "h:\django_learn\env\lib\site-packages\django\core\handlers\base.py", line 115, in _get_response
    response = self.process_exception_by_middleware(e, request)
  File "h:\django_learn\env\lib\site-packages\django\core\handlers\base.py", line 113, in _get_response
    response = wrapped_callback(request, *callback_args, **callback_kwargs)
  File "H:\django_learn\hello\hello\views.py", line 10, in hello
    return JsonResponse(json.dumps(g1))
  File "h:\django_learn\env\lib\site-packages\django\http\response.py", line 581, in __init__
    'In order to allow non-dict objects to be serialized set the '
TypeError: In order to allow non-dict objects to be serialized set the safe parameter to False.
2020-01-22 20:41:26,441 - log.py[line:228] - ERROR: Internal Server Error: /index/
Traceback (most recent call last):
  File "h:\django_learn\env\lib\site-packages\django\core\handlers\exception.py", line 34, in inner
    response = get_response(request)
  File "h:\django_learn\env\lib\site-packages\django\core\handlers\base.py", line 115, in _get_response
    response = self.process_exception_by_middleware(e, request)
  File "h:\django_learn\env\lib\site-packages\django\core\handlers\base.py", line 113, in _get_response
    response = wrapped_callback(request, *callback_args, **callback_kwargs)
  File "H:\django_learn\hello\hello\views.py", line 10, in hello
    return JsonResponse(g1, safe=False,encoder="utf-8")
  File "h:\django_learn\env\lib\site-packages\django\http\response.py", line 587, in __init__
    data = json.dumps(data, cls=encoder, **json_dumps_params)
  File "c:\users\17835\anaconda3\Lib\json\__init__.py", line 238, in dumps
    **kw).encode(obj)
TypeError: 'str' object is not callable
2020-01-22 21:19:45,555 - log.py[line:228] - WARNING: Not Found: /course
2020-01-22 21:43:22,688 - log.py[line:228] - WARNING: Not Found: /grade
2020-01-22 21:53:44,260 - log.py[line:228] - ERROR: Internal Server Error: /grade/
Traceback (most recent call last):
  File "h:\django_learn\env\lib\site-packages\django\core\handlers\exception.py", line 34, in inner
    response = get_response(request)
  File "h:\django_learn\env\lib\site-packages\django\core\handlers\base.py", line 115, in _get_response
    response = self.process_exception_by_middleware(e, request)
  File "h:\django_learn\env\lib\site-packages\django\core\handlers\base.py", line 113, in _get_response
    response = wrapped_callback(request, *callback_args, **callback_kwargs)
  File "H:\django_learn\hello\hello\views.py", line 35, in grade
    return HttpResponse(json.dumps(res, ensure_ascii=False), content_type="application/json,charset=utf-8")
  File "c:\users\17835\anaconda3\Lib\json\__init__.py", line 238, in dumps
    **kw).encode(obj)
  File "c:\users\17835\anaconda3\Lib\json\encoder.py", line 199, in encode
    chunks = self.iterencode(o, _one_shot=True)
  File "c:\users\17835\anaconda3\Lib\json\encoder.py", line 257, in iterencode
    return _iterencode(o, 0)
  File "c:\users\17835\anaconda3\Lib\json\encoder.py", line 179, in default
    raise TypeError(f'Object of type {o.__class__.__name__} '
TypeError: Object of type Response is not JSON serializable
2020-01-22 21:55:00,161 - log.py[line:228] - WARNING: Not Found: /grade/images/fg.png
2020-01-22 21:57:08,225 - log.py[line:228] - WARNING: Not Found: /grade/images/fg.png
2020-01-22 21:58:08,628 - log.py[line:228] - WARNING: Not Found: /grade/images/fg.png
2020-01-22 22:41:46,895 - log.py[line:228] - WARNING: Not Found: /grade/images/fg.png
2020-01-22 23:00:40,325 - log.py[line:228] - WARNING: Not Found: /grade/images/fg.png
2020-01-22 23:00:40,325 - log.py[line:228] - WARNING: Not Found: /grade/images/fg.png
2020-01-22 23:34:01,232 - log.py[line:228] - ERROR: Internal Server Error: /grade/
Traceback (most recent call last):
  File "h:\django_learn\env\lib\site-packages\django\core\handlers\exception.py", line 34, in inner
    response = get_response(request)
  File "h:\django_learn\env\lib\site-packages\django\core\handlers\base.py", line 115, in _get_response
    response = self.process_exception_by_middleware(e, request)
  File "h:\django_learn\env\lib\site-packages\django\core\handlers\base.py", line 113, in _get_response
    response = wrapped_callback(request, *callback_args, **callback_kwargs)
  File "H:\django_learn\hello\hello\views.py", line 31, in grade
    res = jw_login(url=url,  username=username,  password=password)
  File "H:\django_learn\hello\ehall\login.py", line 75, in jw_login
    for cookie in cookies:
TypeError: 'module' object is not iterable
2020-01-22 23:38:47,710 - log.py[line:228] - WARNING: Not Found: /grade/images/fg.png
2020-01-22 23:39:47,905 - log.py[line:228] - WARNING: Not Found: /grade/images/fg.png
2020-01-22 23:40:19,385 - log.py[line:228] - WARNING: Not Found: /grade/images/fg.png
2020-01-22 23:43:17,960 - log.py[line:228] - WARNING: Not Found: /grade/images/fg.png
2020-01-22 23:51:30,904 - log.py[line:228] - WARNING: Not Found: /grade/images/fg.png
