2020-01-23 23:37:45,051 - log.py[line:228]             - ERROR: Internal Server Error: /grade/
Traceback (most recent call last):
  File "h:\django_learn\env\lib\site-packages\django\core\handlers\exception.py", line 34, in inner
    response = get_response(request)
  File "h:\django_learn\env\lib\site-packages\django\core\handlers\base.py", line 115, in _get_response
    response = self.process_exception_by_middleware(e, request)
  File "h:\django_learn\env\lib\site-packages\django\core\handlers\base.py", line 113, in _get_response
    response = wrapped_callback(request, *callback_args, **callback_kwargs)
  File "H:\django_learn\hello\hello\views.py", line 29, in grade
    res = jw_login(username=username, password=password)
  File "H:\django_learn\hello\ehall\login.py", line 86, in jw_login
    driver = getDriver()
TypeError: getDriver() missing 1 required positional argument: 'browser_path'
2020-01-23 23:39:35,939 - log.py[line:228]             - ERROR: Internal Server Error: /grade/
Traceback (most recent call last):
  File "h:\django_learn\env\lib\site-packages\django\core\handlers\exception.py", line 34, in inner
    response = get_response(request)
  File "h:\django_learn\env\lib\site-packages\django\core\handlers\base.py", line 115, in _get_response
    response = self.process_exception_by_middleware(e, request)
  File "h:\django_learn\env\lib\site-packages\django\core\handlers\base.py", line 113, in _get_response
    response = wrapped_callback(request, *callback_args, **callback_kwargs)
  File "H:\django_learn\hello\hello\views.py", line 32, in grade
    return HttpResponse(xueqi, chengji, content_type="application/json,charset=utf-8")
  File "h:\django_learn\env\lib\site-packages\django\http\response.py", line 291, in __init__
    super().__init__(*args, **kwargs)
TypeError: __init__() got multiple values for argument 'content_type'
2020-01-24 01:03:59,192 - log.py[line:228]             - ERROR: Internal Server Error: /grade/
Traceback (most recent call last):
  File "h:\django_learn\env\lib\site-packages\django\core\handlers\exception.py", line 34, in inner
    response = get_response(request)
  File "h:\django_learn\env\lib\site-packages\django\core\handlers\base.py", line 115, in _get_response
    response = self.process_exception_by_middleware(e, request)
  File "h:\django_learn\env\lib\site-packages\django\core\handlers\base.py", line 113, in _get_response
    response = wrapped_callback(request, *callback_args, **callback_kwargs)
  File "H:\django_learn\hello\hello\views.py", line 13, in deco
    re = fun(*args, **kwargs)
  File "H:\django_learn\hello\hello\views.py", line 38, in grade
    res = jw_login(username=username, password=password)
  File "H:\django_learn\hello\ehall\login.py", line 101, in jw_login
    driver = getDriver()
  File "H:\django_learn\hello\ehall\login.py", line 19, in deco
    print(fun.__name__+"函数耗时" + (end-begin)+"秒")
TypeError: can only concatenate str (not "float") to str
2020-01-24 01:05:24,752 - log.py[line:228]             - ERROR: Internal Server Error: /grade/
Traceback (most recent call last):
  File "h:\django_learn\env\lib\site-packages\django\core\handlers\exception.py", line 34, in inner
    response = get_response(request)
  File "h:\django_learn\env\lib\site-packages\django\core\handlers\base.py", line 115, in _get_response
    response = self.process_exception_by_middleware(e, request)
  File "h:\django_learn\env\lib\site-packages\django\core\handlers\base.py", line 113, in _get_response
    response = wrapped_callback(request, *callback_args, **callback_kwargs)
  File "H:\django_learn\hello\hello\views.py", line 15, in deco
    print(fun.__name__+"函数耗时" + (end-begin)+"秒")
TypeError: can only concatenate str (not "float") to str
2020-01-24 01:53:06,937 - log.py[line:228]             - ERROR: Internal Server Error: /grade/
Traceback (most recent call last):
  File "h:\django_learn\env\lib\site-packages\django\core\handlers\exception.py", line 34, in inner
    response = get_response(request)
  File "h:\django_learn\env\lib\site-packages\django\core\handlers\base.py", line 115, in _get_response
    response = self.process_exception_by_middleware(e, request)
  File "h:\django_learn\env\lib\site-packages\django\core\handlers\base.py", line 113, in _get_response
    response = wrapped_callback(request, *callback_args, **callback_kwargs)
  File "H:\django_learn\hello\hello\views.py", line 14, in deco
    re = fun(*args, **kwargs)
  File "H:\django_learn\hello\hello\views.py", line 37, in grade
    res = jw_login(username=username, password=password)
  File "H:\django_learn\hello\ehall\login.py", line 17, in deco
    re = fun(*args, **kwargs)
  File "H:\django_learn\hello\ehall\login.py", line 127, in jw_login
    xueqi = driver.find_element_by_xpath("//input[@id='hfSemesterFramework']")
  File "h:\django_learn\env\lib\site-packages\selenium\webdriver\remote\webdriver.py", line 394, in find_element_by_xpath
    return self.find_element(by=By.XPATH, value=xpath)
  File "h:\django_learn\env\lib\site-packages\selenium\webdriver\remote\webdriver.py", line 978, in find_element
    'value': value})['value']
  File "h:\django_learn\env\lib\site-packages\selenium\webdriver\remote\webdriver.py", line 321, in execute
    self.error_handler.check_response(response)
  File "h:\django_learn\env\lib\site-packages\selenium\webdriver\remote\errorhandler.py", line 242, in check_response
    raise exception_class(message, screen, stacktrace)
selenium.common.exceptions.NoSuchElementException: Message: {"errorMessage":"Unable to find element with xpath '//input[@id='hfSemesterFramework']'","request":{"headers":{"Accept":"application/json","Accept-Encoding":"identity","Content-Length":"118","Content-Type":"application/json;charset=UTF-8","Host":"127.0.0.1:51804","User-Agent":"selenium/3.141.0 (python windows)"},"httpVersion":"1.1","method":"POST","post":"{\"using\": \"xpath\", \"value\": \"//input[@id='hfSemesterFramework']\", \"sessionId\": \"2e3e6410-3e09-11ea-aa5a-e1ce7a37af58\"}","url":"/element","urlParsed":{"anchor":"","query":"","file":"element","directory":"/","path":"/element","relative":"/element","port":"","host":"","password":"","user":"","userInfo":"","authority":"","protocol":"","source":"/element","queryKey":{},"chunks":["element"]},"urlOriginal":"/session/2e3e6410-3e09-11ea-aa5a-e1ce7a37af58/element"}}
Screenshot: available via screen

2020-01-24 12:49:16,306 - log.py[line:228]             - ERROR: Internal Server Error: /grade/
Traceback (most recent call last):
  File "h:\django_learn\env\lib\site-packages\django\core\handlers\exception.py", line 34, in inner
    response = get_response(request)
  File "h:\django_learn\env\lib\site-packages\django\core\handlers\base.py", line 115, in _get_response
    response = self.process_exception_by_middleware(e, request)
  File "h:\django_learn\env\lib\site-packages\django\core\handlers\base.py", line 113, in _get_response
    response = wrapped_callback(request, *callback_args, **callback_kwargs)
  File "H:\django_learn\hello\hello\views.py", line 14, in deco
    re = fun(*args, **kwargs)
  File "H:\django_learn\hello\hello\views.py", line 37, in grade
    res = jw_login(username=username, password=password)
  File "H:\django_learn\hello\ehall\login.py", line 17, in deco
    re = fun(*args, **kwargs)
  File "H:\django_learn\hello\ehall\login.py", line 127, in jw_login
    xueqi = driver.find_element_by_xpath("//input[@id='hfSemesterFramework']")
  File "h:\django_learn\env\lib\site-packages\selenium\webdriver\remote\webdriver.py", line 394, in find_element_by_xpath
    return self.find_element(by=By.XPATH, value=xpath)
  File "h:\django_learn\env\lib\site-packages\selenium\webdriver\remote\webdriver.py", line 978, in find_element
    'value': value})['value']
  File "h:\django_learn\env\lib\site-packages\selenium\webdriver\remote\webdriver.py", line 321, in execute
    self.error_handler.check_response(response)
  File "h:\django_learn\env\lib\site-packages\selenium\webdriver\remote\errorhandler.py", line 242, in check_response
    raise exception_class(message, screen, stacktrace)
selenium.common.exceptions.NoSuchElementException: Message: {"errorMessage":"Unable to find element with xpath '//input[@id='hfSemesterFramework']'","request":{"headers":{"Accept":"application/json","Accept-Encoding":"identity","Content-Length":"118","Content-Type":"application/json;charset=UTF-8","Host":"127.0.0.1:55288","User-Agent":"selenium/3.141.0 (python windows)"},"httpVersion":"1.1","method":"POST","post":"{\"using\": \"xpath\", \"value\": \"//input[@id='hfSemesterFramework']\", \"sessionId\": \"d7cb5460-3e64-11ea-8b93-99680291ea49\"}","url":"/element","urlParsed":{"anchor":"","query":"","file":"element","directory":"/","path":"/element","relative":"/element","port":"","host":"","password":"","user":"","userInfo":"","authority":"","protocol":"","source":"/element","queryKey":{},"chunks":["element"]},"urlOriginal":"/session/d7cb5460-3e64-11ea-8b93-99680291ea49/element"}}
Screenshot: available via screen

2020-01-24 12:49:16,932 - log.py[line:228]             - WARNING: Not Found: /favicon.ico
2020-01-24 12:50:09,342 - log.py[line:228]             - ERROR: Internal Server Error: /grade/
Traceback (most recent call last):
  File "h:\django_learn\env\lib\site-packages\django\core\handlers\exception.py", line 34, in inner
    response = get_response(request)
  File "h:\django_learn\env\lib\site-packages\django\core\handlers\base.py", line 115, in _get_response
    response = self.process_exception_by_middleware(e, request)
  File "h:\django_learn\env\lib\site-packages\django\core\handlers\base.py", line 113, in _get_response
    response = wrapped_callback(request, *callback_args, **callback_kwargs)
  File "H:\django_learn\hello\hello\views.py", line 14, in deco
    re = fun(*args, **kwargs)
  File "H:\django_learn\hello\hello\views.py", line 37, in grade
    res = jw_login(username=username, password=password)
  File "H:\django_learn\hello\ehall\login.py", line 17, in deco
    re = fun(*args, **kwargs)
  File "H:\django_learn\hello\ehall\login.py", line 127, in jw_login
    xueqi = driver.find_element_by_xpath("//input[@id='hfSemesterFramework']")
  File "h:\django_learn\env\lib\site-packages\selenium\webdriver\remote\webdriver.py", line 394, in find_element_by_xpath
    return self.find_element(by=By.XPATH, value=xpath)
  File "h:\django_learn\env\lib\site-packages\selenium\webdriver\remote\webdriver.py", line 978, in find_element
    'value': value})['value']
  File "h:\django_learn\env\lib\site-packages\selenium\webdriver\remote\webdriver.py", line 321, in execute
    self.error_handler.check_response(response)
  File "h:\django_learn\env\lib\site-packages\selenium\webdriver\remote\errorhandler.py", line 242, in check_response
    raise exception_class(message, screen, stacktrace)
selenium.common.exceptions.NoSuchElementException: Message: {"errorMessage":"Unable to find element with xpath '//input[@id='hfSemesterFramework']'","request":{"headers":{"Accept":"application/json","Accept-Encoding":"identity","Content-Length":"118","Content-Type":"application/json;charset=UTF-8","Host":"127.0.0.1:55434","User-Agent":"selenium/3.141.0 (python windows)"},"httpVersion":"1.1","method":"POST","post":"{\"using\": \"xpath\", \"value\": \"//input[@id='hfSemesterFramework']\", \"sessionId\": \"f73f3d70-3e64-11ea-a36b-3f61354ccb4a\"}","url":"/element","urlParsed":{"anchor":"","query":"","file":"element","directory":"/","path":"/element","relative":"/element","port":"","host":"","password":"","user":"","userInfo":"","authority":"","protocol":"","source":"/element","queryKey":{},"chunks":["element"]},"urlOriginal":"/session/f73f3d70-3e64-11ea-a36b-3f61354ccb4a/element"}}
Screenshot: available via screen

2020-01-24 12:50:09,342 - log.py[line:228]             - ERROR: Internal Server Error: /grade/
Traceback (most recent call last):
  File "h:\django_learn\env\lib\site-packages\django\core\handlers\exception.py", line 34, in inner
    response = get_response(request)
  File "h:\django_learn\env\lib\site-packages\django\core\handlers\base.py", line 115, in _get_response
    response = self.process_exception_by_middleware(e, request)
  File "h:\django_learn\env\lib\site-packages\django\core\handlers\base.py", line 113, in _get_response
    response = wrapped_callback(request, *callback_args, **callback_kwargs)
  File "H:\django_learn\hello\hello\views.py", line 14, in deco
    re = fun(*args, **kwargs)
  File "H:\django_learn\hello\hello\views.py", line 37, in grade
    res = jw_login(username=username, password=password)
  File "H:\django_learn\hello\ehall\login.py", line 17, in deco
    re = fun(*args, **kwargs)
  File "H:\django_learn\hello\ehall\login.py", line 127, in jw_login
    xueqi = driver.find_element_by_xpath("//input[@id='hfSemesterFramework']")
  File "h:\django_learn\env\lib\site-packages\selenium\webdriver\remote\webdriver.py", line 394, in find_element_by_xpath
    return self.find_element(by=By.XPATH, value=xpath)
  File "h:\django_learn\env\lib\site-packages\selenium\webdriver\remote\webdriver.py", line 978, in find_element
    'value': value})['value']
  File "h:\django_learn\env\lib\site-packages\selenium\webdriver\remote\webdriver.py", line 321, in execute
    self.error_handler.check_response(response)
  File "h:\django_learn\env\lib\site-packages\selenium\webdriver\remote\errorhandler.py", line 242, in check_response
    raise exception_class(message, screen, stacktrace)
selenium.common.exceptions.NoSuchElementException: Message: {"errorMessage":"Unable to find element with xpath '//input[@id='hfSemesterFramework']'","request":{"headers":{"Accept":"application/json","Accept-Encoding":"identity","Content-Length":"118","Content-Type":"application/json;charset=UTF-8","Host":"127.0.0.1:55434","User-Agent":"selenium/3.141.0 (python windows)"},"httpVersion":"1.1","method":"POST","post":"{\"using\": \"xpath\", \"value\": \"//input[@id='hfSemesterFramework']\", \"sessionId\": \"f73f3d70-3e64-11ea-a36b-3f61354ccb4a\"}","url":"/element","urlParsed":{"anchor":"","query":"","file":"element","directory":"/","path":"/element","relative":"/element","port":"","host":"","password":"","user":"","userInfo":"","authority":"","protocol":"","source":"/element","queryKey":{},"chunks":["element"]},"urlOriginal":"/session/f73f3d70-3e64-11ea-a36b-3f61354ccb4a/element"}}
Screenshot: available via screen

2020-01-24 13:05:49,110 - log.py[line:228]             - ERROR: Internal Server Error: /grade/
Traceback (most recent call last):
  File "h:\django_learn\env\lib\site-packages\django\core\handlers\exception.py", line 34, in inner
    response = get_response(request)
  File "h:\django_learn\env\lib\site-packages\django\utils\deprecation.py", line 96, in __call__
    response = self.process_response(request, response)
  File "h:\django_learn\env\lib\site-packages\django\middleware\clickjacking.py", line 26, in process_response
    if response.get('X-Frame-Options') is not None:
AttributeError: 'tuple' object has no attribute 'get'
2020-01-24 13:20:09,576 - log.py[line:228]             - ERROR: Internal Server Error: /grade/
Traceback (most recent call last):
  File "h:\django_learn\env\lib\site-packages\django\core\handlers\exception.py", line 34, in inner
    response = get_response(request)
  File "h:\django_learn\env\lib\site-packages\django\core\handlers\base.py", line 115, in _get_response
    response = self.process_exception_by_middleware(e, request)
  File "h:\django_learn\env\lib\site-packages\django\core\handlers\base.py", line 113, in _get_response
    response = wrapped_callback(request, *callback_args, **callback_kwargs)
  File "H:\django_learn\hello\hello\views.py", line 16, in deco
    re = fun(*args, **kwargs)
  File "H:\django_learn\hello\hello\views.py", line 42, in grade
    return JsonResponse(xueqi, chengji)
  File "h:\django_learn\env\lib\site-packages\django\http\response.py", line 581, in __init__
    'In order to allow non-dict objects to be serialized set the '
TypeError: In order to allow non-dict objects to be serialized set the safe parameter to False.
2020-01-24 13:20:58,945 - log.py[line:228]             - ERROR: Internal Server Error: /grade/
Traceback (most recent call last):
  File "h:\django_learn\env\lib\site-packages\django\core\handlers\exception.py", line 34, in inner
    response = get_response(request)
  File "h:\django_learn\env\lib\site-packages\django\core\handlers\base.py", line 115, in _get_response
    response = self.process_exception_by_middleware(e, request)
  File "h:\django_learn\env\lib\site-packages\django\core\handlers\base.py", line 113, in _get_response
    response = wrapped_callback(request, *callback_args, **callback_kwargs)
  File "H:\django_learn\hello\hello\views.py", line 16, in deco
    re = fun(*args, **kwargs)
  File "H:\django_learn\hello\hello\views.py", line 42, in grade
    return JsonResponse([xueqi, chengji])
  File "h:\django_learn\env\lib\site-packages\django\http\response.py", line 581, in __init__
    'In order to allow non-dict objects to be serialized set the '
TypeError: In order to allow non-dict objects to be serialized set the safe parameter to False.
2020-01-24 13:22:08,203 - log.py[line:228]             - ERROR: Internal Server Error: /grade/
Traceback (most recent call last):
  File "h:\django_learn\env\lib\site-packages\django\core\handlers\exception.py", line 34, in inner
    response = get_response(request)
  File "h:\django_learn\env\lib\site-packages\django\core\handlers\base.py", line 115, in _get_response
    response = self.process_exception_by_middleware(e, request)
  File "h:\django_learn\env\lib\site-packages\django\core\handlers\base.py", line 113, in _get_response
    response = wrapped_callback(request, *callback_args, **callback_kwargs)
  File "H:\django_learn\hello\hello\views.py", line 16, in deco
    re = fun(*args, **kwargs)
  File "H:\django_learn\hello\hello\views.py", line 42, in grade
    return JsonResponse([xueqi, chengji], safe=False)
  File "h:\django_learn\env\lib\site-packages\django\http\response.py", line 587, in __init__
    data = json.dumps(data, cls=encoder, **json_dumps_params)
  File "c:\users\17835\anaconda3\Lib\json\__init__.py", line 238, in dumps
    **kw).encode(obj)
  File "c:\users\17835\anaconda3\Lib\json\encoder.py", line 199, in encode
    chunks = self.iterencode(o, _one_shot=True)
  File "c:\users\17835\anaconda3\Lib\json\encoder.py", line 257, in iterencode
    return _iterencode(o, 0)
  File "h:\django_learn\env\lib\site-packages\django\core\serializers\json.py", line 104, in default
    return super().default(o)
  File "c:\users\17835\anaconda3\Lib\json\encoder.py", line 179, in default
    raise TypeError(f'Object of type {o.__class__.__name__} '
TypeError: Object of type bytes is not JSON serializable
2020-01-24 13:25:14,172 - log.py[line:228]             - ERROR: Internal Server Error: /grade/
Traceback (most recent call last):
  File "h:\django_learn\env\lib\site-packages\django\core\handlers\exception.py", line 34, in inner
    response = get_response(request)
  File "h:\django_learn\env\lib\site-packages\django\core\handlers\base.py", line 115, in _get_response
    response = self.process_exception_by_middleware(e, request)
  File "h:\django_learn\env\lib\site-packages\django\core\handlers\base.py", line 113, in _get_response
    response = wrapped_callback(request, *callback_args, **callback_kwargs)
  File "H:\django_learn\hello\hello\views.py", line 16, in deco
    re = fun(*args, **kwargs)
  File "H:\django_learn\hello\hello\views.py", line 42, in grade
    return JsonResponse(xueqi, chengji, safe=False)
  File "h:\django_learn\env\lib\site-packages\django\http\response.py", line 587, in __init__
    data = json.dumps(data, cls=encoder, **json_dumps_params)
  File "c:\users\17835\anaconda3\Lib\json\__init__.py", line 238, in dumps
    **kw).encode(obj)
TypeError: 'bytes' object is not callable
2020-01-24 13:27:26,271 - log.py[line:228]             - ERROR: Internal Server Error: /grade/
Traceback (most recent call last):
  File "h:\django_learn\env\lib\site-packages\django\core\handlers\exception.py", line 34, in inner
    response = get_response(request)
  File "h:\django_learn\env\lib\site-packages\django\core\handlers\base.py", line 115, in _get_response
    response = self.process_exception_by_middleware(e, request)
  File "h:\django_learn\env\lib\site-packages\django\core\handlers\base.py", line 113, in _get_response
    response = wrapped_callback(request, *callback_args, **callback_kwargs)
  File "H:\django_learn\hello\hello\views.py", line 16, in deco
    re = fun(*args, **kwargs)
  File "H:\django_learn\hello\hello\views.py", line 42, in grade
    return JsonResponse(xueqi, chengji, safe=False )
  File "h:\django_learn\env\lib\site-packages\django\http\response.py", line 587, in __init__
    data = json.dumps(data, cls=encoder, **json_dumps_params)
  File "c:\users\17835\anaconda3\Lib\json\__init__.py", line 238, in dumps
    **kw).encode(obj)
TypeError: 'str' object is not callable
2020-01-24 13:29:44,012 - log.py[line:228]             - ERROR: Internal Server Error: /grade/
Traceback (most recent call last):
  File "h:\django_learn\env\lib\site-packages\django\core\handlers\exception.py", line 34, in inner
    response = get_response(request)
  File "h:\django_learn\env\lib\site-packages\django\core\handlers\base.py", line 115, in _get_response
    response = self.process_exception_by_middleware(e, request)
  File "h:\django_learn\env\lib\site-packages\django\core\handlers\base.py", line 113, in _get_response
    response = wrapped_callback(request, *callback_args, **callback_kwargs)
  File "H:\django_learn\hello\hello\views.py", line 16, in deco
    re = fun(*args, **kwargs)
  File "H:\django_learn\hello\hello\views.py", line 42, in grade
    return JsonResponse(json.dumps(xueqi), json.dumps(chengji), safe=False)
  File "h:\django_learn\env\lib\site-packages\django\http\response.py", line 587, in __init__
    data = json.dumps(data, cls=encoder, **json_dumps_params)
  File "c:\users\17835\anaconda3\Lib\json\__init__.py", line 238, in dumps
    **kw).encode(obj)
TypeError: 'str' object is not callable
2020-01-25 01:36:20,261 - log.py[line:228]             - ERROR: Internal Server Error: /grade/
Traceback (most recent call last):
  File "h:\django_learn\env\lib\site-packages\django\core\handlers\exception.py", line 34, in inner
    response = get_response(request)
  File "h:\django_learn\env\lib\site-packages\django\core\handlers\base.py", line 115, in _get_response
    response = self.process_exception_by_middleware(e, request)
  File "h:\django_learn\env\lib\site-packages\django\core\handlers\base.py", line 113, in _get_response
    response = wrapped_callback(request, *callback_args, **callback_kwargs)
  File "H:\django_learn\hello\hello\views.py", line 16, in deco
    re = fun(*args, **kwargs)
  File "H:\django_learn\hello\hello\views.py", line 39, in grade
    res = jw_login(username=username, password=password)
  File "H:\django_learn\hello\ehall\login.py", line 17, in deco
    re = fun(*args, **kwargs)
  File "H:\django_learn\hello\ehall\login.py", line 127, in jw_login
    xueqi = driver.find_element_by_xpath("//input[@id='hfSemesterFramework']")
  File "h:\django_learn\env\lib\site-packages\selenium\webdriver\remote\webdriver.py", line 394, in find_element_by_xpath
    return self.find_element(by=By.XPATH, value=xpath)
  File "h:\django_learn\env\lib\site-packages\selenium\webdriver\remote\webdriver.py", line 978, in find_element
    'value': value})['value']
  File "h:\django_learn\env\lib\site-packages\selenium\webdriver\remote\webdriver.py", line 321, in execute
    self.error_handler.check_response(response)
  File "h:\django_learn\env\lib\site-packages\selenium\webdriver\remote\errorhandler.py", line 242, in check_response
    raise exception_class(message, screen, stacktrace)
selenium.common.exceptions.NoSuchElementException: Message: {"errorMessage":"Unable to find element with xpath '//input[@id='hfSemesterFramework']'","request":{"headers":{"Accept":"application/json","Accept-Encoding":"identity","Content-Length":"118","Content-Type":"application/json;charset=UTF-8","Host":"127.0.0.1:51718","User-Agent":"selenium/3.141.0 (python windows)"},"httpVersion":"1.1","method":"POST","post":"{\"using\": \"xpath\", \"value\": \"//input[@id='hfSemesterFramework']\", \"sessionId\": \"fb7e6b20-3ecf-11ea-885a-536bae3d900c\"}","url":"/element","urlParsed":{"anchor":"","query":"","file":"element","directory":"/","path":"/element","relative":"/element","port":"","host":"","password":"","user":"","userInfo":"","authority":"","protocol":"","source":"/element","queryKey":{},"chunks":["element"]},"urlOriginal":"/session/fb7e6b20-3ecf-11ea-885a-536bae3d900c/element"}}
Screenshot: available via screen

2020-01-25 01:39:06,817 - log.py[line:228]             - ERROR: Internal Server Error: /grade/
Traceback (most recent call last):
  File "h:\django_learn\env\lib\site-packages\django\core\handlers\exception.py", line 34, in inner
    response = get_response(request)
  File "h:\django_learn\env\lib\site-packages\django\core\handlers\base.py", line 115, in _get_response
    response = self.process_exception_by_middleware(e, request)
  File "h:\django_learn\env\lib\site-packages\django\core\handlers\base.py", line 113, in _get_response
    response = wrapped_callback(request, *callback_args, **callback_kwargs)
  File "H:\django_learn\hello\hello\views.py", line 16, in deco
    re = fun(*args, **kwargs)
  File "H:\django_learn\hello\hello\views.py", line 40, in grade
    res.encode('utf-8')
AttributeError: 'tuple' object has no attribute 'encode'
